Workbook
Name ПластикатИзоляции: 'Данные ТНПА'!$T$1:$T$7
Name ПлотностьИзоляции: Нормы!#REF!
Name ПлотностьКорделя: Нормы!#REF!
Name ПлотностьОболочки: Нормы!#REF!
Name ПлотностьПояснойИзоляции: Нормы!#REF!
Name ТипОболочки: 'Данные ТНПА'!$AB$1:$AB$7

Sheet Нормы
A1: Т - стобец в котором данные взяты из ТНПА ---> | R1: Т | BV1: Т
A2: ГОСТ 16442-80 | H2: Волочение проволоки | I2: Скрутка жилы | Q2: Заготовка опрессованная | Y2: Кордель выпрессованный | Z2: Заготовка скрученная | BU2: Кабель опрессованный | BX2: Расход материалов, кг/км | CL2: Расчётная масса кабеля | CM2: Алюминий | CN2: Медь | CO2: ПВХ изоляция | CP2: ПВХ оболочка
A3: Марка кабеля | B3: Номинальное напряжение, кВ | C3: Материал жилы. | D3: Число жил и сечение, мм2 | G3: Тип жилы | I3: Число и диаметр проволок в жиле, мм | L3: Данные жилы | Q3: Изоляция | Y3: Диаметр корделя, мм | Z3: Диаметр по скрутке изоли- рованных жил, мм | AA3: Нить п/э | AC3: Лента ПЭТ | AI3: Обмотка сердечника полотном иглопробивным термоскрепленым | AO3: Обмотка лентой ПВХ | AU3: Обмотка лентой ПЭ | BA3: Внутренняя оболочка | BD3: ЛЭС | BI3: Броня из стальных оцинкованных лкент | BO3: Экран из медных лент | BU3: =IF(BI9>0,"Защитный шланг","Наружная оболочка") -> Наружная оболочка | CM3: Катанка алюминиевая А1 | CN3: Катанка медная М-01 | CO3: Кабельный пластикат И40-13А | CP3: Кабельный пластикат ОМ-40
M4: Ширина сектора, мм | N4: r | O4: Прорисованное сечение, мм | P4: Периметр, мм | CM4: Катанка алюминиевая А2 | CN4: Катанка медная М-101 | CO4: Кабельный пластикат И40-13 | CP4: Кабельный пластикат М-10
L5: Диаметр круглой жилы, мм | Q5: радиальная толщина, мм | S5: наружные размеры, мм | AA5: кол., шт. | AB5: номинальный наружный размер, мм | AC5: кол., шт. | AD5: толщина×ширина, мм | AG5: Величина перекрытия, % | AH5: номинальный наружный размер, мм | AI5: кол. лент, шт | AJ5: толщина × ширина, мм | AM5: перекрытие, % | AN5: наружный размер, мм | AO5: кол. лент, шт | AP5: толщина × ширина, мм | AS5: перекрытие, % | AT5: наружный размер, мм | AU5: кол. лент, шт | AV5: толщина × ширина, мм | AY5: перекрытие, % | AZ5: наружный размер, мм | BA5: Радиальная толщина, мм | BC5: Наружный размер, мм | BD5: кол., шт. | BE5: толщина, мм. | BF5: ширина, мм. | BG5: величина перекрытия, % | BH5: диаметр по ленте, мм. | BI5: кол., шт. | BJ5: толщина×ширина, мм | BM5: величина зазора, % | BN5: ном. наружный размер, мм | BO5: кол. лент, шт | BP5: толщина × ширина, мм | BS5: перекрытие, % | BT5: ном. наружный размер, мм | BU5: радиальная толщина, мм | BW5: Ном. наружный размер, мм. | BX5: Алюминий | BY5: Медь | BZ5: ПВХ изоляция | CA5: Кабельный пластикат НГП (втор. перераб.) | CB5: Нить п/э техническая многокруточная структуры 111 текс х2х3 | CC5: Лента ПЭТ | CD5: Полотно иглопробивное термоскрепленое | CE5: Лента ПВХ | CF5: Лента ПЭ | CG5: Кабельный пластикат НГП 30-32 | CH5: Стеклолента ЛЭС | CI5: Лента оцинкованная | CJ5: Медная лента | CK5: ПВХ оболочка | CP5: Cable compaund PVC 1235
BA7: мин. | BB7: ном. | BC7: ном.
Q8: мин. | R8: ном. | S8: мин. | V8: ном. | BU8: мин. | BV8: ном.
A9: ВВГ | AA9: 0 | AC9: 2 | AI9: 0 | AJ9: =IF(AI9=0,0,0.5) -> 0 | AL9: =IF(AI9=0,0,60) -> 0 | AO9: =AI9 -> 0 | AP9: =IF(AO9=0,0,0.5) -> 0 | AR9: =IF(AI9=0,0,60) -> 0 | AU9: =AO9 -> 0 | AV9: =IF(AU9=0,0,0.5) -> 0 | AX9: =IF(AI9=0,0,60) -> 0 | BD9: 0 | BE9: =IF(BD9>0,0.2,0) -> 0 | BG9: =IF(BD9>0,30,0) -> 0 | BI9: 0 | BJ9: =IF(BI9=0,0,0.25) -> 0 | BM9: =IF(BI9=0,0,35) -> 0 | BO9: 0 | BP9: =IF(BO9>0,0.1,0) -> 0 | BS9: 35 | BX9: 2.7 | BY9: 8.89 | BZ9: 1.34 | CA9: =IF(CA5="Кабельный пластикат ПВХ (втор. перераб.)",#REF!, IF(CA5="Кабельный пластикат ПВХ нг-LS (втор. перераб.)",#REF!, IF(CA5="Кабельный пластикат НГП (втор. перераб.)",#REF!, IF(CA5="Композиция безгалогенная марки Винтес 3020",#REF!, IF(CA5="Кабельный пластикат ПВХ ХЛ(втор. перераб.)",#REF!, "ошибка"))))) -> #REF! | CB9: 0.69 | CC9: 1.4 | CD9: 0.32 | CE9: 1.487 | CF9: 0.89 | CG9: =IF(CG5="Кабельный пластикат ОМ-40",#REF!, IF(CG5="Кабельный пластикат НГП 30-32",#REF!, IF(CG5="Резиноподобный наполнитель WK 75/25",#REF!, IF(CG5="Кабельный полиэтилен 102-10 КУ ВС",#REF!, IF(CG5="Кабельный пластикат ППО 30-35",#REF!, IF(CG5="Кабельный пластикат ППВ 28",#REF!, IF(CG5="Кабельный пластикат НГП 40-32 (-50C)",#REF!, IF(CG5="Кабельный пластикат Лоусгран 3110 АЭС",#REF!, "ошибка")))))))) -> #REF! | CH9: 1.15 | CI9: 7.8 | CJ9: 8.89 | CK9: 1.4
A10: =IF(D10="",CONCATENATE("Кабель ",IF(C10="а","А",""),$A$9),CONCATENATE("Кабель ",IF(C10="а","А",""),$A$9," ",D10,"*",F10,IF(G10="ок"," (ож)","")," - ",B10," ",IF(G10="мс"," фас. ",""),$A$2)) -> Кабель ВВГ 1*16 - 0,66 ГОСТ 16442-80 | B10: 0.66 | D10: 1 | E10: × | F10: 16 | G10: мк | H10: 1.77 | I10: 7 | J10: × | K10: =ROUNDUP(SQRT(F10/I10/PI()*4*1.07),2) -> 1.77 | L10: 1.39 | Q10: =0.9*R10-0.1 -> 0.71 | R10: =IF(B10=0.66,VLOOKUP(F10,'Данные ТНПА'!$B$8:$C$16,2,0), IF(B10=1,VLOOKUP(F10,'Данные ТНПА'!$B$17:$C$37,2,0),"ошибка")) -> 0.9 | S10: =IF(I10=1,K10+2*Q10,L10+2*Q10) -> 2.81 | V10: =IF(I10=1,K10+2*R10,L10+2*R10) -> 3.19 | Y10: =IF(V10="","",ROUND(V10*IF(AND(D10=4,F10>16),0.414,IF(D10=5,0.702,0)),1)) -> 0 | Z10: =IF(R10="","", IF(G10="мс",2*(V10+(N10+R10)*(1/COS(PI()*(D10-2)/(2*D10))-1)), IF(D10=1,V10*1,IF(D10=2,V10*2,IF(D10=3,V10*2.15,IF(D10=4,V10*2.41,IF(D10=5,V10*2.7,"ошибка"))))))) -> 3.19 | AA10: =IF(G10="","",IF(G10="мс",$AA$9,0)) -> 0 | AB10: =IF(Z10="","",Z10) -> 3.19 | AC10: =IF(G10="","",IF(G10="мс",$AC$9,0)) -> 0 | AD10: =IF(AC10="","",IF(AC10>0,IF(AND(Z10>=10,Z10<=20),0.035,IF(Z10>20,0.05,"ошибка")),0)) -> 0 | AE10: =IF(Z10="","",IF(AND(G10="мс",AC10>0),"×","")) | AF10: =IF(AC10="","",IF(AC10>0,IF(AND(Z10>=10,Z10<=20),50,IF(Z10>20,60,"ошибка")),0)) -> 0 | AG10: =IF(AC10="","",IF(AC10>0,IF(AND(Z10>=10,Z10<=13),40,IF(AND(Z10>=13,Z10<=16),30,IF(Z10>16,25,"ошибка"))),0)) -> 0 | AH10: =IF(Z10="","",IF(AND(G10="мс",AC10>0),Z10+2*AC10*AD10*IF(AG10<=25,1,IF(AG10>33,2,1.5)),Z10)) -> 3.19 | AI10: =IF(OR($AI$9=0,AH10<=10,D10=1,AND(D10>1,F10<=10,OR(G10="ок",G10="мк"))),0,1) -> 0 | AJ10: =IF(AI10=0,0,$AJ$9) -> 0 | AK10: =IF(AI10="","",IF(AI10=0,0,"×")) -> 0 | AL10: =IF(AI10=0,0,$AL$9) -> 0 | AM10: =IF(AI10=0,0, IF(AND(AH10>10,AH10<=13),55, IF(AND(AH10>13,AH10<=15),45, IF(AND(AH10>15,AH10<=18),35, IF(AND(AH10>18,AH10<=20),30, IF(AH10>20,15, 0)))))) -> 0 | AN10: =AH10+2*AI10*AJ10*(IF(AM10<25,1,IF(AM10>33,2,1.5))) -> 3.19 | AO10: =IF(OR(AI10=0,AN10<=10,AN10>23,AND(D10>1,F10<=10,OR(G10="ок",G10="мк"))),0,1) -> 0 | AP10: =IF(OR(AO10=0,AN10>23),0,$AP$9) -> 0 | AQ10: =IF(OR(AN10>23,AO10=0),0,"×") -> 0 | AR10: =IF(OR(AN10>23,AO10=0),0,$AR$9) -> 0 | AS10: =IF(AO10=0,0, IF(AND(AH10>10,AH10<=13),55, IF(AND(AH10>13,AH10<=15),45, IF(AND(AH10>15,AH10<=18),35, IF(AND(AH10>18,AH10<=20),30, IF(AND(AH10>20,AH10<=23),15, 0)))))) -> 0 | AT10: =AN10+2*AO10*AP10*(IF(AS10<25,1,IF(AS10>33,2,1.5))) -> 3.19 | AU10: =IF(OR(AI10=0,D10=1,AN10<=23),0,1) -> 0 | AV10: =IF(OR(AU10=0,AN10<=23),0,$AV$9) -> 0 | AW10: =IF(OR(AN10<=23,AU10=0),0,"×") -> 0 | AX10: =IF(OR(AN10<=23,AU10=0),0,$AX$9) -> 0 | AY10: =IF(AU10=0,0,15) -> 0 | AZ10: =AT10+2*AU10*AV10*(IF(AY10<25,1,IF(AY10>33,2,1.5))) -> 3.19 | BA10: =IF(BB10=0,0, IF(D10=1, (IF(AND(AH10>'Данные ТНПА'!#REF!,AH10<='Данные ТНПА'!#REF!),'Данные ТНПА'!#REF!, IF(AND(AH10>'Данные ТНПА'!#REF!,AH10<='Данные ТНПА'!#REF!),'Данные ТНПА'!#REF!, IF(AND(AH10>'Данные ТНПА'!#REF!,AH10<='Данные ТНПА'!#REF!),'Данные ТНПА'!#REF!, IF(AND(AH10>'Данные ТНПА'!#REF!,AH10<='Данные ТНПА'!#REF!),'Данные ТНПА'!#REF!, IF(AND(AH10>'Данные ТНПА'!#REF!,AH10<='Данные ТНПА'!#REF!),'Данные ТНПА'!#REF!, IF(AND(AH10>'Данные ТНПА'!#REF!,AH10<='Данные ТНПА'!#REF!),'Данные ТНПА'!#REF!, "ошибка_1"))))))), IF(AND(AH10>'Данные ТНПА'!#REF!,AH10<='Данные ТНПА'!#REF!),'Данные ТНПА'!#REF!, IF(AND(AH10>'Данные ТНПА'!#REF!,AH10<='Данные ТНПА'!#REF!),'Данные ТНПА'!#REF!, IF(AND(AH10>'Данные ТНПА'!#REF!,AH10<='Данные ТНПА'!#REF!),'Данные ТНПА'!#REF!, IF(AND(AH10>'Данные ТНПА'!#REF!,AH10<='Данные ТНПА'!#REF!),'Данные ТНПА'!#REF!, IF(AND(AH10>'Данные ТНПА'!#REF!,AH10<='Данные ТНПА'!#REF!),'Данные ТНПА'!#REF!, IF(AND(AH10>'Данные ТНПА'!#REF!,AH10<='Данные ТНПА'!#REF!),'Данные ТНПА'!#REF!, "ошибка_2")))))))) -> 0 | BB10: =IF(OR($AI$9=0,AND(D10>1,F10>10)),0, IF(D10=1, (IF(AND(AH10>'Данные ТНПА'!#REF!,AH10<='Данные ТНПА'!#REF!),'Данные ТНПА'!#REF!, IF(AND(AH10>'Данные ТНПА'!#REF!,AH10<='Данные ТНПА'!#REF!),'Данные ТНПА'!#REF!, IF(AND(AH10>'Данные ТНПА'!#REF!,AH10<='Данные ТНПА'!#REF!),'Данные ТНПА'!#REF!, IF(AND(AH10>'Данные ТНПА'!#REF!,AH10<='Данные ТНПА'!#REF!),'Данные ТНПА'!#REF!, IF(AND(AH10>'Данные ТНПА'!#REF!,AH10<='Данные ТНПА'!#REF!),'Данные ТНПА'!#REF!, IF(AND(AH10>'Данные ТНПА'!#REF!,AH10<='Данные ТНПА'!#REF!),'Данные ТНПА'!#REF!, "ошибка_1"))))))), IF(AND(AH10>'Данные ТНПА'!#REF!,AH10<='Данные ТНПА'!#REF!),'Данные ТНПА'!#REF!, IF(AND(AH10>'Данные ТНПА'!#REF!,AH10<='Данные ТНПА'!#REF!),'Данные ТНПА'!#REF!, IF(AND(AH10>'Данные ТНПА'!#REF!,AH10<='Данные ТНПА'!#REF!),'Данные ТНПА'!#REF!, IF(AND(AH10>'Данные ТНПА'!#REF!,AH10<='Данные ТНПА'!#REF!),'Данные ТНПА'!#REF!, IF(AND(AH10>'Данные ТНПА'!#REF!,AH10<='Данные ТНПА'!#REF!),'Данные ТНПА'!#REF!, IF(AND(AH10>'Данные ТНПА'!#REF!,AH10<='Данные ТНПА'!#REF!),'Данные ТНПА'!#REF!, "ошибка_2")))))))) -> 0 | BC10: =AZ10+2*BB10 -> 3.19 | BD10: =IF(BC10="","", IF(BC10=0,0,$BD$9)) -> 0 | BE10: =IF(BC10="","", IF(BC10=0,0,$BE$9)) -> 0 | BF10: =IF(BC10="","", IF($BD$9=0,0, IF(BC10<=13,20, IF(AND(BC10>13,BC10<=18),30, IF(AND(BC10>18,BC10<=23),40, IF(AND(BC10>23,BC10<=30),50, 60)))))) -> 0 | BG10: =IF(BC10="","",$BG$9) -> 0 | BH10: =IF(BC10="","",BC10+2*BD10*BE10*IF(BG10<=25,1,IF(BG10>33,2,1.5))) -> 3.19 | BI10: =IF(BC10="","",$BI$9) -> 0 | BJ10: =IF(BC10="","",$BJ$9) -> 0 | BK10: =IF(BJ10="","",IF(BJ10<>0,"×",0)) -> 0 | BL10: =IF(BK10="","", IF(BJ10<>0, IF(AND(BC10>7,BC10<=10),15, IF(AND(BC10>10,BC10<=13),20, IF(AND(BC10>13,BC10<=21),30, IF(AND(BC10>21,BC10<=31),40, IF(AND(BC10>31,BC10<=70),50, IF(AND(BC10>70,BC10<=80),60, "ошибка")))))),0)) -> 0 | BM10: =IF(BL10="","",$BM$9) -> 0 | BN10: =IF(BH10="","",BH10+2*BI10*BJ10) -> 3.19 | BO10: =IF(BN10="","",$BO$9) -> 0 | BP10: =IF(BO10="","",IF(BO10>0,$BP$9,0)) -> 0 | BQ10: =IF(BP10="","",IF(BP10>0,"×","")) | BR10: =IF(BN10="","",IF(BO10=0,0,IF(BN10<=19,30,IF(AND(BN10>19,BN10<=23),40,50)))) -> 0 | BS10: =IF(BO10="","",IF(BO10=0,0,$BS$9)) -> 0 | BT10: =IF(BN10="","",BN10+2*BO10*BP10*IF(BS10<=25,1,IF(BS10>33,2,1.5))) -> 3.19 | BU10: =0.85*BV10-0.1 -> 0.92 | BV10: =IF(BT10="","", IF(AND(BT10>'Данные ТНПА'!$K$8,BT10<='Данные ТНПА'!$L$8),'Данные ТНПА'!$N$8, IF(AND(BT10>'Данные ТНПА'!$K$9,BT10<='Данные ТНПА'!$L$9),'Данные ТНПА'!$N$9, IF(AND(BT10>'Данные ТНПА'!$K$10,BT10<='Данные ТНПА'!$L$10),'Данные ТНПА'!$N$10, IF(AND(BT10>'Данные ТНПА'!$K$11,BT10<='Данные ТНПА'!$L$11),'Данные ТНПА'!$N$11, IF(AND(BT10>'Данные ТНПА'!$K$12,BT10<='Данные ТНПА'!$L$12),'Данные ТНПА'!$N$12, IF(AND(BT10>'Данные ТНПА'!$K$13,BT10<='Данные ТНПА'!$L$13),'Данные ТНПА'!$N$13, IF(AND(BT10>'Данные ТНПА'!$K$14,BT10<='Данные ТНПА'!$L$14),'Данные ТНПА'!$N$14)))))))) -> 1.2 | BW10: =BT10+2*BV10 -> 5.59 | BX10: =IF(C10="а",F10*$BX$9*D10*IF(D10>1,1.007,1),0) -> 0 | BY10: =IF(C10="а",0,F10*$BY$9*D10*IF(D10>1,1.007,1)) -> 142.24 | BZ10: =IF(G10="мс",PI()*(P10/PI()+R10)*R10*$BZ$9*1.13*D10*1.007, PI()*(IF(I10=1,K10,L10)+R10)*R10*$BZ$9*D10*IF(D10>1,1.007,1)*IF(I10=1,1,(IF(F10>=4,1.1,1.07)))) -> 9.5438883 | CA10: =PI()*POWER(Y10,2)/4*$CA$9 -> #REF! | CB10: =IF(AA10="","", IF(AA10=2,SQRT((Z10*PI()/50)^2+1)*$CB$9*AA10,0)) -> 0 | CC10: =PI()*(Z10+AC10*AD10)*AC10*AD10*$CC$9*ROUND(100/(100-AG10),2) -> 0 | CD10: =PI()*(AH10+AI10*AJ10)*AI10*AJ10*$CD$9*ROUND(100/(100-AM10),2) -> 0 | CE10: =PI()*(AN10+AO10*AP10)*AO10*AP10*$CE$9*ROUND(100/(100-AS10),2) -> 0 | CF10: =PI()*(AT10+AU10*AV10)*AU10*AV10*$CF$9*ROUND(100/(100-AY10),2) -> 0 | CG10: =IF(CB10="","", IF(BB10=0,0, IF(AND(G10="мс",AC10=0),(PI()*BC10^2/4-D10*(O10+PI()*(P10/PI()+R10)*R10)-((POWER((N10+R10),2)*(D10*TAN(PI()*((D10-2)/(2*D10)))-(PI()*(D10-2)/2)))))*$CG$9, IF(AND(D10>1,OR(G10="ок",G10="мк")),(PI()*BC10^2/4-PI()*V10^2*(D10+2)/8-D10*(SIN(PI()*(D10-2)/D10))/2*(AB10/2-V10/2)^2)*$CG$9, PI()*(AB10+BB10)*BB10*1.07*$CG$9)))) -> 0 | CH10: =IF(BE10="","", IF(BD10=0,0, PI()*(BC10+BD10*BE10)*BD10*BE10*$CH$9*ROUND(100/(100-BG10),2))) -> 0 | CI10: =IF(BH10="","", PI()*(BH10+BI10*BJ10)*BI10*BJ10*$CI$9*ROUND(100/(100+BM10),2)) -> 0 | CJ10: =IF(BO10="","",PI()*(BN10+BO10*BP10)*BO10*BP10*$CJ$9*ROUND(100/(100-BS10),2)) -> 0 | CK10: =PI()*(BT10+BV10)*BV10*IF($BI$9>0,1.1,1.04)*$CK$9 -> 24.096669 | CL10: =BX10+BY10+BZ10+CK10 -> 175.88056
A11: =IF(D11="",CONCATENATE("Кабель ",IF(C11="а","А",""),$A$9),CONCATENATE("Кабель ",IF(C11="а","А",""),$A$9," ",D11,"*",F11,IF(G11="ок"," (ож)","")," - ",B11," ",IF(G11="мс"," фас. ",""),$A$2)) -> Кабель ВВГ 1*25 - 0,66 ГОСТ 16442-80 | B11: 0.66 | D11: 1 | E11: × | F11: 25 | G11: мк | H11: 2.21 | I11: 7 | J11: × | K11: =ROUNDUP(SQRT(F11/I11/PI()*4*1.07),2) -> 2.21 | L11: 1.79 | Q11: =0.9*R11-0.1 -> 0.89 | R11: =IF(B11=0.66,VLOOKUP(F11,'Данные ТНПА'!$B$8:$C$16,2,0), IF(B11=1,VLOOKUP(F11,'Данные ТНПА'!$B$17:$C$37,2,0),"ошибка")) -> 1.1 | S11: =IF(I11=1,K11+2*Q11,L11+2*Q11) -> 3.57 | V11: =IF(I11=1,K11+2*R11,L11+2*R11) -> 3.99 | Y11: =IF(V11="","",ROUND(V11*IF(AND(D11=4,F11>16),0.414,IF(D11=5,0.702,0)),1)) -> 0 | Z11: =IF(R11="","", IF(G11="мс",2*(V11+(N11+R11)*(1/COS(PI()*(D11-2)/(2*D11))-1)), IF(D11=1,V11*1,IF(D11=2,V11*2,IF(D11=3,V11*2.15,IF(D11=4,V11*2.41,IF(D11=5,V11*2.7,"ошибка"))))))) -> 3.99 | AA11: =IF(G11="","",IF(G11="мс",$AA$9,0)) -> 0 | AB11: =IF(Z11="","",Z11) -> 3.99 | AC11: =IF(G11="","",IF(G11="мс",$AC$9,0)) -> 0 | AD11: =IF(AC11="","",IF(AC11>0,IF(AND(Z11>=10,Z11<=20),0.035,IF(Z11>20,0.05,"ошибка")),0)) -> 0 | AE11: =IF(Z11="","",IF(AND(G11="мс",AC11>0),"×","")) | AF11: =IF(AC11="","",IF(AC11>0,IF(AND(Z11>=10,Z11<=20),50,IF(Z11>20,60,"ошибка")),0)) -> 0 | AG11: =IF(AC11="","",IF(AC11>0,IF(AND(Z11>=10,Z11<=13),40,IF(AND(Z11>=13,Z11<=16),30,IF(Z11>16,25,"ошибка"))),0)) -> 0 | AH11: =IF(Z11="","",IF(AND(G11="мс",AC11>0),Z11+2*AC11*AD11*IF(AG11<=25,1,IF(AG11>33,2,1.5)),Z11)) -> 3.99 | AI11: =AM14 -> 0 | AJ11: =IF(AI11=0,0,$AJ$9) -> 0 | AK11: =IF(AI11="","",IF(AI11=0,0,"×")) -> 0 | AL11: =IF(AI11=0,0,$AL$9) -> 0 | AM11: =IF(AI11=0,0, IF(AND(AH11>10,AH11<=13),55, IF(AND(AH11>13,AH11<=15),45, IF(AND(AH11>15,AH11<=18),35, IF(AND(AH11>18,AH11<=20),30, IF(AH11>20,15, 0)))))) -> 0 | AN11: =AH11+2*AI11*AJ11*(IF(AM11<25,1,IF(AM11>33,2,1.5))) -> 3.99 | AO11: =IF(OR(AI11=0,AN11<=10,AN11>23,AND(D11>1,F11<=10,OR(G11="ок",G11="мк"))),0,1) -> 0 | AP11: =IF(OR(AO11=0,AN11>23),0,$AP$9) -> 0 | AQ11: =IF(OR(AN11>23,AO11=0),0,"×") -> 0 | AR11: =IF(OR(AN11>23,AO11=0),0,$AR$9) -> 0 | AS11: =IF(AO11=0,0, IF(AND(AH11>10,AH11<=13),55, IF(AND(AH11>13,AH11<=15),45, IF(AND(AH11>15,AH11<=18),35, IF(AND(AH11>18,AH11<=20),30, IF(AND(AH11>20,AH11<=23),15, 0)))))) -> 0 | AT11: =AN11+2*AO11*AP11*(IF(AS11<25,1,IF(AS11>33,2,1.5))) -> 3.99 | AU11: =IF(OR(AI11=0,D11=1,AN11<=23),0,1) -> 0 | AV11: =IF(OR(AU11=0,AN11<=23),0,$AV$9) -> 0 | AW11: =IF(OR(AN11<=23,AU11=0),0,"×") -> 0 | AX11: =IF(OR(AN11<=23,AU11=0),0,$AX$9) -> 0 | AY11: =IF(AU11=0,0,15) -> 0 | AZ11: =AT11+2*AU11*AV11*(IF(AY11<25,1,IF(AY11>33,2,1.5))) -> 3.99 | BA11: =IF(BB11=0,0, IF(D11=1, (IF(AND(AH11>'Данные ТНПА'!#REF!,AH11<='Данные ТНПА'!#REF!),'Данные ТНПА'!#REF!, IF(AND(AH11>'Данные ТНПА'!#REF!,AH11<='Данные ТНПА'!#REF!),'Данные ТНПА'!#REF!, IF(AND(AH11>'Данные ТНПА'!#REF!,AH11<='Данные ТНПА'!#REF!),'Данные ТНПА'!#REF!, IF(AND(AH11>'Данные ТНПА'!#REF!,AH11<='Данные ТНПА'!#REF!),'Данные ТНПА'!#REF!, IF(AND(AH11>'Данные ТНПА'!#REF!,AH11<='Данные ТНПА'!#REF!),'Данные ТНПА'!#REF!, IF(AND(AH11>'Данные ТНПА'!#REF!,AH11<='Данные ТНПА'!#REF!),'Данные ТНПА'!#REF!, "ошибка_1"))))))), IF(AND(AH11>'Данные ТНПА'!#REF!,AH11<='Данные ТНПА'!#REF!),'Данные ТНПА'!#REF!, IF(AND(AH11>'Данные ТНПА'!#REF!,AH11<='Данные ТНПА'!#REF!),'Данные ТНПА'!#REF!, IF(AND(AH11>'Данные ТНПА'!#REF!,AH11<='Данные ТНПА'!#REF!),'Данные ТНПА'!#REF!, IF(AND(AH11>'Данные ТНПА'!#REF!,AH11<='Данные ТНПА'!#REF!),'Данные ТНПА'!#REF!, IF(AND(AH11>'Данные ТНПА'!#REF!,AH11<='Данные ТНПА'!#REF!),'Данные ТНПА'!#REF!, IF(AND(AH11>'Данные ТНПА'!#REF!,AH11<='Данные ТНПА'!#REF!),'Данные ТНПА'!#REF!, "ошибка_2")))))))) -> 0 | BB11: =IF(OR($AI$9=0,AND(D11>1,F11>10)),0, IF(D11=1, (IF(AND(AH11>'Данные ТНПА'!#REF!,AH11<='Данные ТНПА'!#REF!),'Данные ТНПА'!#REF!, IF(AND(AH11>'Данные ТНПА'!#REF!,AH11<='Данные ТНПА'!#REF!),'Данные ТНПА'!#REF!, IF(AND(AH11>'Данные ТНПА'!#REF!,AH11<='Данные ТНПА'!#REF!),'Данные ТНПА'!#REF!, IF(AND(AH11>'Данные ТНПА'!#REF!,AH11<='Данные ТНПА'!#REF!),'Данные ТНПА'!#REF!, IF(AND(AH11>'Данные ТНПА'!#REF!,AH11<='Данные ТНПА'!#REF!),'Данные ТНПА'!#REF!, IF(AND(AH11>'Данные ТНПА'!#REF!,AH11<='Данные ТНПА'!#REF!),'Данные ТНПА'!#REF!, "ошибка_1"))))))), IF(AND(AH11>'Данные ТНПА'!#REF!,AH11<='Данные ТНПА'!#REF!),'Данные ТНПА'!#REF!, IF(AND(AH11>'Данные ТНПА'!#REF!,AH11<='Данные ТНПА'!#REF!),'Данные ТНПА'!#REF!, IF(AND(AH11>'Данные ТНПА'!#REF!,AH11<='Данные ТНПА'!#REF!),'Данные ТНПА'!#REF!, IF(AND(AH11>'Данные ТНПА'!#REF!,AH11<='Данные ТНПА'!#REF!),'Данные ТНПА'!#REF!, IF(AND(AH11>'Данные ТНПА'!#REF!,AH11<='Данные ТНПА'!#REF!),'Данные ТНПА'!#REF!, IF(AND(AH11>'Данные ТНПА'!#REF!,AH11<='Данные ТНПА'!#REF!),'Данные ТНПА'!#REF!, "ошибка_2")))))))) -> 0 | BC11: =AZ11+2*BB11 -> 3.99 | BD11: =IF(BC11="","", IF(BC11=0,0,$BD$9)) -> 0 | BE11: =IF(BC11="","", IF(BC11=0,0,$BE$9)) -> 0 | BF11: =IF(BC11="","", IF($BD$9=0,0, IF(BC11<=13,20, IF(AND(BC11>13,BC11<=18),30, IF(AND(BC11>18,BC11<=23),40, IF(AND(BC11>23,BC11<=30),50, 60)))))) -> 0 | BG11: =IF(BC11="","",$BG$9) -> 0 | BH11: =IF(BC11="","",BC11+2*BD11*BE11*IF(BG11<=25,1,IF(BG11>33,2,1.5))) -> 3.99 | BI11: =IF(BC11="","",$BI$9) -> 0 | BJ11: =IF(BC11="","",$BJ$9) -> 0 | BK11: =IF(BJ11="","",IF(BJ11<>0,"×",0)) -> 0 | BL11: =IF(BK11="","", IF(BJ11<>0, IF(AND(BC11>7,BC11<=10),15, IF(AND(BC11>10,BC11<=13),20, IF(AND(BC11>13,BC11<=21),30, IF(AND(BC11>21,BC11<=31),40, IF(AND(BC11>31,BC11<=70),50, IF(AND(BC11>70,BC11<=80),60, "ошибка")))))),0)) -> 0 | BM11: =IF(BL11="","",$BM$9) -> 0 | BN11: =IF(BH11="","",BH11+2*BI11*BJ11) -> 3.99 | BO11: =IF(BN11="","",$BO$9) -> 0 | BP11: =IF(BO11="","",IF(BO11>0,$BP$9,0)) -> 0 | BQ11: =IF(BP11="","",IF(BP11>0,"×","")) | BR11: =IF(BN11="","",IF(BO11=0,0,IF(BN11<=19,30,IF(AND(BN11>19,BN11<=23),40,50)))) -> 0 | BS11: =IF(BO11="","",IF(BO11=0,0,$BS$9)) -> 0 | BT11: =IF(BN11="","",BN11+2*BO11*BP11*IF(BS11<=25,1,IF(BS11>33,2,1.5))) -> 3.99 | BU11: =0.85*BV11-0.1 -> 0.92 | BV11: =IF(BT11="","", IF(AND(BT11>'Данные ТНПА'!$K$8,BT11<='Данные ТНПА'!$L$8),'Данные ТНПА'!$N$8, IF(AND(BT11>'Данные ТНПА'!$K$9,BT11<='Данные ТНПА'!$L$9),'Данные ТНПА'!$N$9, IF(AND(BT11>'Данные ТНПА'!$K$10,BT11<='Данные ТНПА'!$L$10),'Данные ТНПА'!$N$10, IF(AND(BT11>'Данные ТНПА'!$K$11,BT11<='Данные ТНПА'!$L$11),'Данные ТНПА'!$N$11, IF(AND(BT11>'Данные ТНПА'!$K$12,BT11<='Данные ТНПА'!$L$12),'Данные ТНПА'!$N$12, IF(AND(BT11>'Данные ТНПА'!$K$13,BT11<='Данные ТНПА'!$L$13),'Данные ТНПА'!$N$13, IF(AND(BT11>'Данные ТНПА'!$K$14,BT11<='Данные ТНПА'!$L$14),'Данные ТНПА'!$N$14)))))))) -> 1.2 | BW11: =BT11+2*BV11 -> 6.39 | BX11: =IF(C11="а",F11*$BX$9*D11*IF(D11>1,1.007,1),0) -> 0 | BY11: =IF(C11="а",0,F11*$BY$9*D11*IF(D11>1,1.007,1)) -> 222.25 | BZ11: =IF(G11="мс",PI()*(P11/PI()+R11)*R11*$BZ$9*1.13*D11*1.007, PI()*(IF(I11=1,K11,L11)+R11)*R11*$BZ$9*D11*IF(D11>1,1.007,1)*IF(I11=1,1,(IF(F11>=4,1.1,1.07)))) -> 14.721019 | CA11: =PI()*POWER(Y11,2)/4*$CA$9 -> #REF! | CB11: =IF(AA11="","", IF(AA11=2,SQRT((Z11*PI()/50)^2+1)*$CB$9*AA11,0)) -> 0 | CC11: =PI()*(Z11+AC11*AD11)*AC11*AD11*$CC$9*ROUND(100/(100-AG11),2) -> 0 | CD11: =PI()*(AH11+AI11*AJ11)*AI11*AJ11*$CD$9*ROUND(100/(100-AM11),2) -> 0 | CE11: =PI()*(AN11+AO11*AP11)*AO11*AP11*$CE$9*ROUND(100/(100-AS11),2) -> 0 | CF11: =PI()*(AT11+AU11*AV11)*AU11*AV11*$CF$9*ROUND(100/(100-AY11),2) -> 0 | CG11: =IF(CB11="","", IF(BB11=0,0, IF(AND(G11="мс",AC11=0),(PI()*BC11^2/4-D11*(O11+PI()*(P11/PI()+R11)*R11)-((POWER((N11+R11),2)*(D11*TAN(PI()*((D11-2)/(2*D11)))-(PI()*(D11-2)/2)))))*$CG$9, IF(AND(D11>1,OR(G11="ок",G11="мк")),(PI()*BC11^2/4-PI()*V11^2*(D11+2)/8-D11*(SIN(PI()*(D11-2)/D11))/2*(AB11/2-V11/2)^2)*$CG$9, PI()*(AB11+BB11)*BB11*1.07*$CG$9)))) -> 0 | CH11: =IF(BE11="","", IF(BD11=0,0, PI()*(BC11+BD11*BE11)*BD11*BE11*$CH$9*ROUND(100/(100-BG11),2))) -> 0 | CI11: =IF(BH11="","", PI()*(BH11+BI11*BJ11)*BI11*BJ11*$CI$9*ROUND(100/(100+BM11),2)) -> 0 | CJ11: =IF(BO11="","",PI()*(BN11+BO11*BP11)*BO11*BP11*$CJ$9*ROUND(100/(100-BS11),2)) -> 0 | CK11: =PI()*(BT11+BV11)*BV11*IF($BI$9>0,1.1,1.04)*$CK$9 -> 28.487862 | CL11: =BX11+BY11+BZ11+CK11 -> 265.45888
A12: =IF(D12="",CONCATENATE("Кабель ",IF(C12="а","А",""),$A$9),CONCATENATE("Кабель ",IF(C12="а","А",""),$A$9," ",D12,"*",F12,IF(G12="ок"," (ож)","")," - ",B12," ",IF(G12="мс"," фас. ",""),$A$2)) -> Кабель ВВГ 1*35 - 0,66 ГОСТ 16442-80 | B12: 0.66 | D12: 1 | E12: × | F12: 35 | G12: мк | H12: 2.61 | I12: 7 | J12: × | K12: =ROUNDUP(SQRT(F12/I12/PI()*4*1.07),2) -> 2.61 | L12: 2.26 | Q12: =0.9*R12-0.1 -> 0.89 | R12: =IF(B12=0.66,VLOOKUP(F12,'Данные ТНПА'!$B$8:$C$16,2,0), IF(B12=1,VLOOKUP(F12,'Данные ТНПА'!$B$17:$C$37,2,0),"ошибка")) -> 1.1 | S12: =IF(I12=1,K12+2*Q12,L12+2*Q12) -> 4.04 | V12: =IF(I12=1,K12+2*R12,L12+2*R12) -> 4.46 | Y12: =IF(V12="","",ROUND(V12*IF(AND(D12=4,F12>16),0.414,IF(D12=5,0.702,0)),1)) -> 0 | Z12: =IF(R12="","", IF(G12="мс",2*(V12+(N12+R12)*(1/COS(PI()*(D12-2)/(2*D12))-1)), IF(D12=1,V12*1,IF(D12=2,V12*2,IF(D12=3,V12*2.15,IF(D12=4,V12*2.41,IF(D12=5,V12*2.7,"ошибка"))))))) -> 4.46 | AA12: =IF(G12="","",IF(G12="мс",$AA$9,0)) -> 0 | AB12: =IF(Z12="","",Z12) -> 4.46 | AC12: =IF(G12="","",IF(G12="мс",$AC$9,0)) -> 0 | AD12: =IF(AC12="","",IF(AC12>0,IF(AND(Z12>=10,Z12<=20),0.035,IF(Z12>20,0.05,"ошибка")),0)) -> 0 | AE12: =IF(Z12="","",IF(AND(G12="мс",AC12>0),"×","")) | AF12: =IF(AC12="","",IF(AC12>0,IF(AND(Z12>=10,Z12<=20),50,IF(Z12>20,60,"ошибка")),0)) -> 0 | AG12: =IF(AC12="","",IF(AC12>0,IF(AND(Z12>=10,Z12<=13),40,IF(AND(Z12>=13,Z12<=16),30,IF(Z12>16,25,"ошибка"))),0)) -> 0 | AH12: =IF(Z12="","",IF(AND(G12="мс",AC12>0),Z12+2*AC12*AD12*IF(AG12<=25,1,IF(AG12>33,2,1.5)),Z12)) -> 4.46 | AI12: =IF(OR($AI$9=0,AH12<=10,D12=1,AND(D12>1,F12<=10,OR(G12="ок",G12="мк"))),0,1) -> 0 | AJ12: =IF(AI12=0,0,$AJ$9) -> 0 | AK12: =IF(AI12="","",IF(AI12=0,0,"×")) -> 0 | AL12: =IF(AI12=0,0,$AL$9) -> 0 | AM12: =IF(AI12=0,0, IF(AND(AH12>10,AH12<=13),55, IF(AND(AH12>13,AH12<=15),45, IF(AND(AH12>15,AH12<=18),35, IF(AND(AH12>18,AH12<=20),30, IF(AH12>20,15, 0)))))) -> 0 | AN12: =AH12+2*AI12*AJ12*(IF(AM12<25,1,IF(AM12>33,2,1.5))) -> 4.46 | AO12: =IF(OR(AI12=0,AN12<=10,AN12>23,AND(D12>1,F12<=10,OR(G12="ок",G12="мк"))),0,1) -> 0 | AP12: =IF(OR(AO12=0,AN12>23),0,$AP$9) -> 0 | AQ12: =IF(OR(AN12>23,AO12=0),0,"×") -> 0 | AR12: =IF(OR(AN12>23,AO12=0),0,$AR$9) -> 0 | AS12: =IF(AO12=0,0, IF(AND(AH12>10,AH12<=13),55, IF(AND(AH12>13,AH12<=15),45, IF(AND(AH12>15,AH12<=18),35, IF(AND(AH12>18,AH12<=20),30, IF(AND(AH12>20,AH12<=23),15, 0)))))) -> 0 | AT12: =AN12+2*AO12*AP12*(IF(AS12<25,1,IF(AS12>33,2,1.5))) -> 4.46 | AU12: =IF(OR(AI12=0,D12=1,AN12<=23),0,1) -> 0 | AV12: =IF(OR(AU12=0,AN12<=23),0,$AV$9) -> 0 | AW12: =IF(OR(AN12<=23,AU12=0),0,"×") -> 0 | AX12: =IF(OR(AN12<=23,AU12=0),0,$AX$9) -> 0 | AY12: =IF(AU12=0,0,15) -> 0 | AZ12: =AT12+2*AU12*AV12*(IF(AY12<25,1,IF(AY12>33,2,1.5))) -> 4.46 | BA12: =IF(BB12=0,0, IF(D12=1, (IF(AND(AH12>'Данные ТНПА'!#REF!,AH12<='Данные ТНПА'!#REF!),'Данные ТНПА'!#REF!, IF(AND(AH12>'Данные ТНПА'!#REF!,AH12<='Данные ТНПА'!#REF!),'Данные ТНПА'!#REF!, IF(AND(AH12>'Данные ТНПА'!#REF!,AH12<='Данные ТНПА'!#REF!),'Данные ТНПА'!#REF!, IF(AND(AH12>'Данные ТНПА'!#REF!,AH12<='Данные ТНПА'!#REF!),'Данные ТНПА'!#REF!, IF(AND(AH12>'Данные ТНПА'!#REF!,AH12<='Данные ТНПА'!#REF!),'Данные ТНПА'!#REF!, IF(AND(AH12>'Данные ТНПА'!#REF!,AH12<='Данные ТНПА'!#REF!),'Данные ТНПА'!#REF!, "ошибка_1"))))))), IF(AND(AH12>'Данные ТНПА'!#REF!,AH12<='Данные ТНПА'!#REF!),'Данные ТНПА'!#REF!, IF(AND(AH12>'Данные ТНПА'!#REF!,AH12<='Данные ТНПА'!#REF!),'Данные ТНПА'!#REF!, IF(AND(AH12>'Данные ТНПА'!#REF!,AH12<='Данные ТНПА'!#REF!),'Данные ТНПА'!#REF!, IF(AND(AH12>'Данные ТНПА'!#REF!,AH12<='Данные ТНПА'!#REF!),'Данные ТНПА'!#REF!, IF(AND(AH12>'Данные ТНПА'!#REF!,AH12<='Данные ТНПА'!#REF!),'Данные ТНПА'!#REF!, IF(AND(AH12>'Данные ТНПА'!#REF!,AH12<='Данные ТНПА'!#REF!),'Данные ТНПА'!#REF!, "ошибка_2")))))))) -> 0 | BB12: =IF(OR($AI$9=0,AND(D12>1,F12>10)),0, IF(D12=1, (IF(AND(AH12>'Данные ТНПА'!#REF!,AH12<='Данные ТНПА'!#REF!),'Данные ТНПА'!#REF!, IF(AND(AH12>'Данные ТНПА'!#REF!,AH12<='Данные ТНПА'!#REF!),'Данные ТНПА'!#REF!, IF(AND(AH12>'Данные ТНПА'!#REF!,AH12<='Данные ТНПА'!#REF!),'Данные ТНПА'!#REF!, IF(AND(AH12>'Данные ТНПА'!#REF!,AH12<='Данные ТНПА'!#REF!),'Данные ТНПА'!#REF!, IF(AND(AH12>'Данные ТНПА'!#REF!,AH12<='Данные ТНПА'!#REF!),'Данные ТНПА'!#REF!, IF(AND(AH12>'Данные ТНПА'!#REF!,AH12<='Данные ТНПА'!#REF!),'Данные ТНПА'!#REF!, "ошибка_1"))))))), IF(AND(AH12>'Данные ТНПА'!#REF!,AH12<='Данные ТНПА'!#REF!),'Данные ТНПА'!#REF!, IF(AND(AH12>'Данные ТНПА'!#REF!,AH12<='Данные ТНПА'!#REF!),'Данные ТНПА'!#REF!, IF(AND(AH12>'Данные ТНПА'!#REF!,AH12<='Данные ТНПА'!#REF!),'Данные ТНПА'!#REF!, IF(AND(AH12>'Данные ТНПА'!#REF!,AH12<='Данные ТНПА'!#REF!),'Данные ТНПА'!#REF!, IF(AND(AH12>'Данные ТНПА'!#REF!,AH12<='Данные ТНПА'!#REF!),'Данные ТНПА'!#REF!, IF(AND(AH12>'Данные ТНПА'!#REF!,AH12<='Данные ТНПА'!#REF!),'Данные ТНПА'!#REF!, "ошибка_2")))))))) -> 0 | BC12: =AZ12+2*BB12 -> 4.46 | BD12: =IF(BC12="","", IF(BC12=0,0,$BD$9)) -> 0 | BE12: =IF(BC12="","", IF(BC12=0,0,$BE$9)) -> 0 | BF12: =IF(BC12="","", IF($BD$9=0,0, IF(BC12<=13,20, IF(AND(BC12>13,BC12<=18),30, IF(AND(BC12>18,BC12<=23),40, IF(AND(BC12>23,BC12<=30),50, 60)))))) -> 0 | BG12: =IF(BC12="","",$BG$9) -> 0 | BH12: =IF(BC12="","",BC12+2*BD12*BE12*IF(BG12<=25,1,IF(BG12>33,2,1.5))) -> 4.46 | BI12: =IF(BC12="","",$BI$9) -> 0 | BJ12: =IF(BC12="","",$BJ$9) -> 0 | BK12: =IF(BJ12="","",IF(BJ12<>0,"×",0)) -> 0 | BL12: =IF(BK12="","", IF(BJ12<>0, IF(AND(BC12>7,BC12<=10),15, IF(AND(BC12>10,BC12<=13),20, IF(AND(BC12>13,BC12<=21),30, IF(AND(BC12>21,BC12<=31),40, IF(AND(BC12>31,BC12<=70),50, IF(AND(BC12>70,BC12<=80),60, "ошибка")))))),0)) -> 0 | BM12: =IF(BL12="","",$BM$9) -> 0 | BN12: =IF(BH12="","",BH12+2*BI12*BJ12) -> 4.46 | BO12: =IF(BN12="","",$BO$9) -> 0 | BP12: =IF(BO12="","",IF(BO12>0,$BP$9,0)) -> 0 | BQ12: =IF(BP12="","",IF(BP12>0,"×","")) | BR12: =IF(BN12="","",IF(BO12=0,0,IF(BN12<=19,30,IF(AND(BN12>19,BN12<=23),40,50)))) -> 0 | BS12: =IF(BO12="","",IF(BO12=0,0,$BS$9)) -> 0 | BT12: =IF(BN12="","",BN12+2*BO12*BP12*IF(BS12<=25,1,IF(BS12>33,2,1.5))) -> 4.46 | BU12: =0.85*BV12-0.1 -> 0.92 | BV12: =IF(BT12="","", IF(AND(BT12>'Данные ТНПА'!$K$8,BT12<='Данные ТНПА'!$L$8),'Данные ТНПА'!$N$8, IF(AND(BT12>'Данные ТНПА'!$K$9,BT12<='Данные ТНПА'!$L$9),'Данные ТНПА'!$N$9, IF(AND(BT12>'Данные ТНПА'!$K$10,BT12<='Данные ТНПА'!$L$10),'Данные ТНПА'!$N$10, IF(AND(BT12>'Данные ТНПА'!$K$11,BT12<='Данные ТНПА'!$L$11),'Данные ТНПА'!$N$11, IF(AND(BT12>'Данные ТНПА'!$K$12,BT12<='Данные ТНПА'!$L$12),'Данные ТНПА'!$N$12, IF(AND(BT12>'Данные ТНПА'!$K$13,BT12<='Данные ТНПА'!$L$13),'Данные ТНПА'!$N$13, IF(AND(BT12>'Данные ТНПА'!$K$14,BT12<='Данные ТНПА'!$L$14),'Данные ТНПА'!$N$14)))))))) -> 1.2 | BW12: =BT12+2*BV12 -> 6.86 | BX12: =IF(C12="а",F12*$BX$9*D12*IF(D12>1,1.007,1),0) -> 0 | BY12: =IF(C12="а",0,F12*$BY$9*D12*IF(D12>1,1.007,1)) -> 311.15 | BZ12: =IF(G12="мс",PI()*(P12/PI()+R12)*R12*$BZ$9*1.13*D12*1.007, PI()*(IF(I12=1,K12,L12)+R12)*R12*$BZ$9*D12*IF(D12>1,1.007,1)*IF(I12=1,1,(IF(F12>=4,1.1,1.07)))) -> 17.115095 | CA12: =PI()*POWER(Y12,2)/4*$CA$9 -> #REF! | CB12: =IF(AA12="","", IF(AA12=2,SQRT((Z12*PI()/50)^2+1)*$CB$9*AA12,0)) -> 0 | CC12: =PI()*(Z12+AC12*AD12)*AC12*AD12*$CC$9*ROUND(100/(100-AG12),2) -> 0 | CD12: =PI()*(AH12+AI12*AJ12)*AI12*AJ12*$CD$9*ROUND(100/(100-AM12),2) -> 0 | CE12: =PI()*(AN12+AO12*AP12)*AO12*AP12*$CE$9*ROUND(100/(100-AS12),2) -> 0 | CF12: =PI()*(AT12+AU12*AV12)*AU12*AV12*$CF$9*ROUND(100/(100-AY12),2) -> 0 | CG12: =IF(CB12="","", IF(BB12=0,0, IF(AND(G12="мс",AC12=0),(PI()*BC12^2/4-D12*(O12+PI()*(P12/PI()+R12)*R12)-((POWER((N12+R12),2)*(D12*TAN(PI()*((D12-2)/(2*D12)))-(PI()*(D12-2)/2)))))*$CG$9, IF(AND(D12>1,OR(G12="ок",G12="мк")),(PI()*BC12^2/4-PI()*V12^2*(D12+2)/8-D12*(SIN(PI()*(D12-2)/D12))/2*(AB12/2-V12/2)^2)*$CG$9, PI()*(AB12+BB12)*BB12*1.07*$CG$9)))) -> 0 | CH12: =IF(BE12="","", IF(BD12=0,0, PI()*(BC12+BD12*BE12)*BD12*BE12*$CH$9*ROUND(100/(100-BG12),2))) -> 0 | CI12: =IF(BH12="","", PI()*(BH12+BI12*BJ12)*BI12*BJ12*$CI$9*ROUND(100/(100+BM12),2)) -> 0 | CJ12: =IF(BO12="","",PI()*(BN12+BO12*BP12)*BO12*BP12*$CJ$9*ROUND(100/(100-BS12),2)) -> 0 | CK12: =PI()*(BT12+BV12)*BV12*IF($BI$9>0,1.1,1.04)*$CK$9 -> 31.067687 | CL12: =BX12+BY12+BZ12+CK12 -> 359.33278
A13: =IF(D13="",CONCATENATE("Кабель ",IF(C13="а","А",""),$A$9),CONCATENATE("Кабель ",IF(C13="а","А",""),$A$9," ",D13,"*",F13,IF(G13="ок"," (ож)","")," - ",B13," ",IF(G13="мс"," фас. ",""),$A$2)) -> Кабель ВВГ 1*50 - 0,66 ГОСТ 16442-80 | B13: 0.66 | D13: 1 | E13: × | F13: 50 | G13: мк | H13: 3.12 | I13: 7 | J13: × | K13: =ROUNDUP(SQRT(F13/I13/PI()*4*1.07),2) -> 3.12 | L13: 2.77 | Q13: =0.9*R13-0.1 -> 1.07 | R13: =IF(B13=0.66,VLOOKUP(F13,'Данные ТНПА'!$B$8:$C$16,2,0), IF(B13=1,VLOOKUP(F13,'Данные ТНПА'!$B$17:$C$37,2,0),"ошибка")) -> 1.3 | S13: =IF(I13=1,K13+2*Q13,L13+2*Q13) -> 4.91 | V13: =IF(I13=1,K13+2*R13,L13+2*R13) -> 5.37 | Y13: =IF(V13="","",ROUND(V13*IF(AND(D13=4,F13>16),0.414,IF(D13=5,0.702,0)),1)) -> 0 | Z13: =IF(R13="","", IF(G13="мс",2*(V13+(N13+R13)*(1/COS(PI()*(D13-2)/(2*D13))-1)), IF(D13=1,V13*1,IF(D13=2,V13*2,IF(D13=3,V13*2.15,IF(D13=4,V13*2.41,IF(D13=5,V13*2.7,"ошибка"))))))) -> 5.37 | AA13: =IF(G13="","",IF(G13="мс",$AA$9,0)) -> 0 | AB13: =IF(Z13="","",Z13) -> 5.37 | AC13: =IF(G13="","",IF(G13="мс",$AC$9,0)) -> 0 | AD13: =IF(AC13="","",IF(AC13>0,IF(AND(Z13>=10,Z13<=20),0.035,IF(Z13>20,0.05,"ошибка")),0)) -> 0 | AE13: =IF(Z13="","",IF(AND(G13="мс",AC13>0),"×","")) | AF13: =IF(AC13="","",IF(AC13>0,IF(AND(Z13>=10,Z13<=20),50,IF(Z13>20,60,"ошибка")),0)) -> 0 | AG13: =IF(AC13="","",IF(AC13>0,IF(AND(Z13>=10,Z13<=13),40,IF(AND(Z13>=13,Z13<=16),30,IF(Z13>16,25,"ошибка"))),0)) -> 0 | AH13: =IF(Z13="","",IF(AND(G13="мс",AC13>0),Z13+2*AC13*AD13*IF(AG13<=25,1,IF(AG13>33,2,1.5)),Z13)) -> 5.37 | AI13: =IF(OR($AI$9=0,AH13<=10,D13=1,AND(D13>1,F13<=10,OR(G13="ок",G13="мк"))),0,1) -> 0 | AJ13: =IF(AI13=0,0,$AJ$9) -> 0 | AK13: =IF(AI13="","",IF(AI13=0,0,"×")) -> 0 | AL13: =IF(AI13=0,0,$AL$9) -> 0 | AM13: =IF(AI13=0,0, IF(AND(AH13>10,AH13<=13),55, IF(AND(AH13>13,AH13<=15),45, IF(AND(AH13>15,AH13<=18),35, IF(AND(AH13>18,AH13<=20),30, IF(AH13>20,15, 0)))))) -> 0 | AN13: =AH13+2*AI13*AJ13*(IF(AM13<25,1,IF(AM13>33,2,1.5))) -> 5.37 | AO13: =IF(OR(AI13=0,AN13<=10,AN13>23,AND(D13>1,F13<=10,OR(G13="ок",G13="мк"))),0,1) -> 0 | AP13: =IF(OR(AO13=0,AN13>23),0,$AP$9) -> 0 | AQ13: =IF(OR(AN13>23,AO13=0),0,"×") -> 0 | AR13: =IF(OR(AN13>23,AO13=0),0,$AR$9) -> 0 | AS13: =IF(AO13=0,0, IF(AND(AH13>10,AH13<=13),55, IF(AND(AH13>13,AH13<=15),45, IF(AND(AH13>15,AH13<=18),35, IF(AND(AH13>18,AH13<=20),30, IF(AND(AH13>20,AH13<=23),15, 0)))))) -> 0 | AT13: =AN13+2*AO13*AP13*(IF(AS13<25,1,IF(AS13>33,2,1.5))) -> 5.37 | AU13: =IF(OR(AI13=0,D13=1,AN13<=23),0,1) -> 0 | AV13: =IF(OR(AU13=0,AN13<=23),0,$AV$9) -> 0 | AW13: =IF(OR(AN13<=23,AU13=0),0,"×") -> 0 | AX13: =IF(OR(AN13<=23,AU13=0),0,$AX$9) -> 0 | AY13: =IF(AU13=0,0,15) -> 0 | AZ13: =AT13+2*AU13*AV13*(IF(AY13<25,1,IF(AY13>33,2,1.5))) -> 5.37 | BA13: =IF(BB13=0,0, IF(D13=1, (IF(AND(AH13>'Данные ТНПА'!#REF!,AH13<='Данные ТНПА'!#REF!),'Данные ТНПА'!#REF!, IF(AND(AH13>'Данные ТНПА'!#REF!,AH13<='Данные ТНПА'!#REF!),'Данные ТНПА'!#REF!, IF(AND(AH13>'Данные ТНПА'!#REF!,AH13<='Данные ТНПА'!#REF!),'Данные ТНПА'!#REF!, IF(AND(AH13>'Данные ТНПА'!#REF!,AH13<='Данные ТНПА'!#REF!),'Данные ТНПА'!#REF!, IF(AND(AH13>'Данные ТНПА'!#REF!,AH13<='Данные ТНПА'!#REF!),'Данные ТНПА'!#REF!, IF(AND(AH13>'Данные ТНПА'!#REF!,AH13<='Данные ТНПА'!#REF!),'Данные ТНПА'!#REF!, "ошибка_1"))))))), IF(AND(AH13>'Данные ТНПА'!#REF!,AH13<='Данные ТНПА'!#REF!),'Данные ТНПА'!#REF!, IF(AND(AH13>'Данные ТНПА'!#REF!,AH13<='Данные ТНПА'!#REF!),'Данные ТНПА'!#REF!, IF(AND(AH13>'Данные ТНПА'!#REF!,AH13<='Данные ТНПА'!#REF!),'Данные ТНПА'!#REF!, IF(AND(AH13>'Данные ТНПА'!#REF!,AH13<='Данные ТНПА'!#REF!),'Данные ТНПА'!#REF!, IF(AND(AH13>'Данные ТНПА'!#REF!,AH13<='Данные ТНПА'!#REF!),'Данные ТНПА'!#REF!, IF(AND(AH13>'Данные ТНПА'!#REF!,AH13<='Данные ТНПА'!#REF!),'Данные ТНПА'!#REF!, "ошибка_2")))))))) -> 0 | BB13: =IF(OR($AI$9=0,AND(D13>1,F13>10)),0, IF(D13=1, (IF(AND(AH13>'Данные ТНПА'!#REF!,AH13<='Данные ТНПА'!#REF!),'Данные ТНПА'!#REF!, IF(AND(AH13>'Данные ТНПА'!#REF!,AH13<='Данные ТНПА'!#REF!),'Данные ТНПА'!#REF!, IF(AND(AH13>'Данные ТНПА'!#REF!,AH13<='Данные ТНПА'!#REF!),'Данные ТНПА'!#REF!, IF(AND(AH13>'Данные ТНПА'!#REF!,AH13<='Данные ТНПА'!#REF!),'Данные ТНПА'!#REF!, IF(AND(AH13>'Данные ТНПА'!#REF!,AH13<='Данные ТНПА'!#REF!),'Данные ТНПА'!#REF!, IF(AND(AH13>'Данные ТНПА'!#REF!,AH13<='Данные ТНПА'!#REF!),'Данные ТНПА'!#REF!, "ошибка_1"))))))), IF(AND(AH13>'Данные ТНПА'!#REF!,AH13<='Данные ТНПА'!#REF!),'Данные ТНПА'!#REF!, IF(AND(AH13>'Данные ТНПА'!#REF!,AH13<='Данные ТНПА'!#REF!),'Данные ТНПА'!#REF!, IF(AND(AH13>'Данные ТНПА'!#REF!,AH13<='Данные ТНПА'!#REF!),'Данные ТНПА'!#REF!, IF(AND(AH13>'Данные ТНПА'!#REF!,AH13<='Данные ТНПА'!#REF!),'Данные ТНПА'!#REF!, IF(AND(AH13>'Данные ТНПА'!#REF!,AH13<='Данные ТНПА'!#REF!),'Данные ТНПА'!#REF!, IF(AND(AH13>'Данные ТНПА'!#REF!,AH13<='Данные ТНПА'!#REF!),'Данные ТНПА'!#REF!, "ошибка_2")))))))) -> 0 | BC13: =AZ13+2*BB13 -> 5.37 | BD13: =IF(BC13="","", IF(BC13=0,0,$BD$9)) -> 0 | BE13: =IF(BC13="","", IF(BC13=0,0,$BE$9)) -> 0 | BF13: =IF(BC13="","", IF($BD$9=0,0, IF(BC13<=13,20, IF(AND(BC13>13,BC13<=18),30, IF(AND(BC13>18,BC13<=23),40, IF(AND(BC13>23,BC13<=30),50, 60)))))) -> 0 | BG13: =IF(BC13="","",$BG$9) -> 0 | BH13: =IF(BC13="","",BC13+2*BD13*BE13*IF(BG13<=25,1,IF(BG13>33,2,1.5))) -> 5.37 | BI13: =IF(BC13="","",$BI$9) -> 0 | BJ13: =IF(BC13="","",$BJ$9) -> 0 | BK13: =IF(BJ13="","",IF(BJ13<>0,"×",0)) -> 0 | BL13: =IF(BK13="","", IF(BJ13<>0, IF(AND(BC13>7,BC13<=10),15, IF(AND(BC13>10,BC13<=13),20, IF(AND(BC13>13,BC13<=21),30, IF(AND(BC13>21,BC13<=31),40, IF(AND(BC13>31,BC13<=70),50, IF(AND(BC13>70,BC13<=80),60, "ошибка")))))),0)) -> 0 | BM13: =IF(BL13="","",$BM$9) -> 0 | BN13: =IF(BH13="","",BH13+2*BI13*BJ13) -> 5.37 | BO13: =IF(BN13="","",$BO$9) -> 0 | BP13: =IF(BO13="","",IF(BO13>0,$BP$9,0)) -> 0 | BQ13: =IF(BP13="","",IF(BP13>0,"×","")) | BR13: =IF(BN13="","",IF(BO13=0,0,IF(BN13<=19,30,IF(AND(BN13>19,BN13<=23),40,50)))) -> 0 | BS13: =IF(BO13="","",IF(BO13=0,0,$BS$9)) -> 0 | BT13: =IF(BN13="","",BN13+2*BO13*BP13*IF(BS13<=25,1,IF(BS13>33,2,1.5))) -> 5.37 | BU13: =0.85*BV13-0.1 -> 0.92 | BV13: =IF(BT13="","", IF(AND(BT13>'Данные ТНПА'!$K$8,BT13<='Данные ТНПА'!$L$8),'Данные ТНПА'!$N$8, IF(AND(BT13>'Данные ТНПА'!$K$9,BT13<='Данные ТНПА'!$L$9),'Данные ТНПА'!$N$9, IF(AND(BT13>'Данные ТНПА'!$K$10,BT13<='Данные ТНПА'!$L$10),'Данные ТНПА'!$N$10, IF(AND(BT13>'Данные ТНПА'!$K$11,BT13<='Данные ТНПА'!$L$11),'Данные ТНПА'!$N$11, IF(AND(BT13>'Данные ТНПА'!$K$12,BT13<='Данные ТНПА'!$L$12),'Данные ТНПА'!$N$12, IF(AND(BT13>'Данные ТНПА'!$K$13,BT13<='Данные ТНПА'!$L$13),'Данные ТНПА'!$N$13, IF(AND(BT13>'Данные ТНПА'!$K$14,BT13<='Данные ТНПА'!$L$14),'Данные ТНПА'!$N$14)))))))) -> 1.2 | BW13: =BT13+2*BV13 -> 7.77 | BX13: =IF(C13="а",F13*$BX$9*D13*IF(D13>1,1.007,1),0) -> 0 | BY13: =IF(C13="а",0,F13*$BY$9*D13*IF(D13>1,1.007,1)) -> 444.5 | BZ13: =IF(G13="мс",PI()*(P13/PI()+R13)*R13*$BZ$9*1.13*D13*1.007, PI()*(IF(I13=1,K13,L13)+R13)*R13*$BZ$9*D13*IF(D13>1,1.007,1)*IF(I13=1,1,(IF(F13>=4,1.1,1.07)))) -> 24.501074 | CA13: =PI()*POWER(Y13,2)/4*$CA$9 -> #REF! | CB13: =IF(AA13="","", IF(AA13=2,SQRT((Z13*PI()/50)^2+1)*$CB$9*AA13,0)) -> 0 | CC13: =PI()*(Z13+AC13*AD13)*AC13*AD13*$CC$9*ROUND(100/(100-AG13),2) -> 0 | CD13: =PI()*(AH13+AI13*AJ13)*AI13*AJ13*$CD$9*ROUND(100/(100-AM13),2) -> 0 | CE13: =PI()*(AN13+AO13*AP13)*AO13*AP13*$CE$9*ROUND(100/(100-AS13),2) -> 0 | CF13: =PI()*(AT13+AU13*AV13)*AU13*AV13*$CF$9*ROUND(100/(100-AY13),2) -> 0 | CG13: =IF(CB13="","", IF(BB13=0,0, IF(AND(G13="мс",AC13=0),(PI()*BC13^2/4-D13*(O13+PI()*(P13/PI()+R13)*R13)-((POWER((N13+R13),2)*(D13*TAN(PI()*((D13-2)/(2*D13)))-(PI()*(D13-2)/2)))))*$CG$9, IF(AND(D13>1,OR(G13="ок",G13="мк")),(PI()*BC13^2/4-PI()*V13^2*(D13+2)/8-D13*(SIN(PI()*(D13-2)/D13))/2*(AB13/2-V13/2)^2)*$CG$9, PI()*(AB13+BB13)*BB13*1.07*$CG$9)))) -> 0 | CH13: =IF(BE13="","", IF(BD13=0,0, PI()*(BC13+BD13*BE13)*BD13*BE13*$CH$9*ROUND(100/(100-BG13),2))) -> 0 | CI13: =IF(BH13="","", PI()*(BH13+BI13*BJ13)*BI13*BJ13*$CI$9*ROUND(100/(100+BM13),2)) -> 0 | CJ13: =IF(BO13="","",PI()*(BN13+BO13*BP13)*BO13*BP13*$CJ$9*ROUND(100/(100-BS13),2)) -> 0 | CK13: =PI()*(BT13+BV13)*BV13*IF($BI$9>0,1.1,1.04)*$CK$9 -> 36.062669 | CL13: =BX13+BY13+BZ13+CK13 -> 505.06374
A14: =IF(D14="",CONCATENATE("Кабель ",IF(C14="а","А",""),$A$9),CONCATENATE("Кабель ",IF(C14="а","А",""),$A$9," ",D14,"*",F14,IF(G14="ок"," (ож)","")," - ",B14," ",IF(G14="мс"," фас. ",""),$A$2)) -> Кабель ВВГ 1*1,5 (ож) - 0,66 ГОСТ 16442-80 | B14: 0.66 | D14: 1 | E14: × | F14: 1.5 | G14: ок | H14: 1.39 | I14: 1 | J14: × | K14: =ROUNDUP(SQRT(F14/PI()*4),2) -> 1.39 | L14: 3.57 | Q14: =0.9*R14-0.1 -> 0.44 | R14: =IF(B14=0.66,VLOOKUP(F14,'Данные ТНПА'!$B$8:$C$16,2,0), IF(B14=1,VLOOKUP(F14,'Данные ТНПА'!$B$17:$C$37,2,0),"ошибка")) -> 0.6 | S14: =IF(I14=1,K14+2*Q14,L14+2*Q14) -> 2.27 | V14: =IF(I14=1,K14+2*R14,L14+2*R14) -> 2.59 | Y14: =IF(V14="","",ROUND(V14*IF(AND(D14=4,F14>16),0.414,IF(D14=5,0.702,0)),1)) -> 0 | Z14: =IF(R14="","", IF(G14="мс",2*(V14+(N14+R14)*(1/COS(PI()*(D14-2)/(2*D14))-1)), IF(D14=1,V14*1,IF(D14=2,V14*2,IF(D14=3,V14*2.15,IF(D14=4,V14*2.41,IF(D14=5,V14*2.7,"ошибка"))))))) -> 2.59 | AA14: =IF(G14="","",IF(G14="мс",$AA$9,0)) -> 0 | AB14: =IF(Z14="","",Z14) -> 2.59 | AC14: =IF(G14="","",IF(G14="мс",$AC$9,0)) -> 0 | AD14: =IF(AC14="","",IF(AC14>0,IF(AND(Z14>=10,Z14<=20),0.035,IF(Z14>20,0.05,"ошибка")),0)) -> 0 | AE14: =IF(Z14="","",IF(AND(G14="мс",AC14>0),"×","")) | AF14: =IF(AC14="","",IF(AC14>0,IF(AND(Z14>=10,Z14<=20),50,IF(Z14>20,60,"ошибка")),0)) -> 0 | AG14: =IF(AC14="","",IF(AC14>0,IF(AND(Z14>=10,Z14<=13),40,IF(AND(Z14>=13,Z14<=16),30,IF(Z14>16,25,"ошибка"))),0)) -> 0 | AH14: =IF(Z14="","",IF(AND(G14="мс",AC14>0),Z14+2*AC14*AD14*IF(AG14<=25,1,IF(AG14>33,2,1.5)),Z14)) -> 2.59 | AI14: =IF(OR($AI$9=0,AH14<=10,D14=1,AND(D14>1,F14<=10,OR(G14="ок",G14="мк"))),0,1) -> 0 | AJ14: =IF(AI14=0,0,$AJ$9) -> 0 | AK14: =IF(AI14="","",IF(AI14=0,0,"×")) -> 0 | AL14: =IF(AI14=0,0,$AL$9) -> 0 | AM14: =IF(AI14=0,0, IF(AND(AH14>10,AH14<=13),55, IF(AND(AH14>13,AH14<=15),45, IF(AND(AH14>15,AH14<=18),35, IF(AND(AH14>18,AH14<=20),30, IF(AH14>20,15, 0)))))) -> 0 | AN14: =AH14+2*AI14*AJ14*(IF(AM14<25,1,IF(AM14>33,2,1.5))) -> 2.59 | AO14: =IF(OR(AI14=0,AN14<=10,AN14>23,AND(D14>1,F14<=10,OR(G14="ок",G14="мк"))),0,1) -> 0 | AP14: =IF(OR(AO14=0,AN14>23),0,$AP$9) -> 0 | AQ14: =IF(OR(AN14>23,AO14=0),0,"×") -> 0 | AR14: =IF(OR(AN14>23,AO14=0),0,$AR$9) -> 0 | AS14: =IF(AO14=0,0, IF(AND(AH14>10,AH14<=13),55, IF(AND(AH14>13,AH14<=15),45, IF(AND(AH14>15,AH14<=18),35, IF(AND(AH14>18,AH14<=20),30, IF(AND(AH14>20,AH14<=23),15, 0)))))) -> 0 | AT14: =AN14+2*AO14*AP14*(IF(AS14<25,1,IF(AS14>33,2,1.5))) -> 2.59 | AU14: =IF(OR(AI14=0,D14=1,AN14<=23),0,1) -> 0 | AV14: =IF(OR(AU14=0,AN14<=23),0,$AV$9) -> 0 | AW14: =IF(OR(AN14<=23,AU14=0),0,"×") -> 0 | AX14: =IF(OR(AN14<=23,AU14=0),0,$AX$9) -> 0 | AY14: =IF(AU14=0,0,15) -> 0 | AZ14: =AT14+2*AU14*AV14*(IF(AY14<25,1,IF(AY14>33,2,1.5))) -> 2.59 | BA14: =IF(BB14=0,0, IF(D14=1, (IF(AND(AH14>'Данные ТНПА'!#REF!,AH14<='Данные ТНПА'!#REF!),'Данные ТНПА'!#REF!, IF(AND(AH14>'Данные ТНПА'!#REF!,AH14<='Данные ТНПА'!#REF!),'Данные ТНПА'!#REF!, IF(AND(AH14>'Данные ТНПА'!#REF!,AH14<='Данные ТНПА'!#REF!),'Данные ТНПА'!#REF!, IF(AND(AH14>'Данные ТНПА'!#REF!,AH14<='Данные ТНПА'!#REF!),'Данные ТНПА'!#REF!, IF(AND(AH14>'Данные ТНПА'!#REF!,AH14<='Данные ТНПА'!#REF!),'Данные ТНПА'!#REF!, IF(AND(AH14>'Данные ТНПА'!#REF!,AH14<='Данные ТНПА'!#REF!),'Данные ТНПА'!#REF!, "ошибка_1"))))))), IF(AND(AH14>'Данные ТНПА'!#REF!,AH14<='Данные ТНПА'!#REF!),'Данные ТНПА'!#REF!, IF(AND(AH14>'Данные ТНПА'!#REF!,AH14<='Данные ТНПА'!#REF!),'Данные ТНПА'!#REF!, IF(AND(AH14>'Данные ТНПА'!#REF!,AH14<='Данные ТНПА'!#REF!),'Данные ТНПА'!#REF!, IF(AND(AH14>'Данные ТНПА'!#REF!,AH14<='Данные ТНПА'!#REF!),'Данные ТНПА'!#REF!, IF(AND(AH14>'Данные ТНПА'!#REF!,AH14<='Данные ТНПА'!#REF!),'Данные ТНПА'!#REF!, IF(AND(AH14>'Данные ТНПА'!#REF!,AH14<='Данные ТНПА'!#REF!),'Данные ТНПА'!#REF!, "ошибка_2")))))))) -> 0 | BB14: =IF(OR($AI$9=0,AND(D14>1,F14>10)),0, IF(D14=1, (IF(AND(AH14>'Данные ТНПА'!#REF!,AH14<='Данные ТНПА'!#REF!),'Данные ТНПА'!#REF!, IF(AND(AH14>'Данные ТНПА'!#REF!,AH14<='Данные ТНПА'!#REF!),'Данные ТНПА'!#REF!, IF(AND(AH14>'Данные ТНПА'!#REF!,AH14<='Данные ТНПА'!#REF!),'Данные ТНПА'!#REF!, IF(AND(AH14>'Данные ТНПА'!#REF!,AH14<='Данные ТНПА'!#REF!),'Данные ТНПА'!#REF!, IF(AND(AH14>'Данные ТНПА'!#REF!,AH14<='Данные ТНПА'!#REF!),'Данные ТНПА'!#REF!, IF(AND(AH14>'Данные ТНПА'!#REF!,AH14<='Данные ТНПА'!#REF!),'Данные ТНПА'!#REF!, "ошибка_1"))))))), IF(AND(AH14>'Данные ТНПА'!#REF!,AH14<='Данные ТНПА'!#REF!),'Данные ТНПА'!#REF!, IF(AND(AH14>'Данные ТНПА'!#REF!,AH14<='Данные ТНПА'!#REF!),'Данные ТНПА'!#REF!, IF(AND(AH14>'Данные ТНПА'!#REF!,AH14<='Данные ТНПА'!#REF!),'Данные ТНПА'!#REF!, IF(AND(AH14>'Данные ТНПА'!#REF!,AH14<='Данные ТНПА'!#REF!),'Данные ТНПА'!#REF!, IF(AND(AH14>'Данные ТНПА'!#REF!,AH14<='Данные ТНПА'!#REF!),'Данные ТНПА'!#REF!, IF(AND(AH14>'Данные ТНПА'!#REF!,AH14<='Данные ТНПА'!#REF!),'Данные ТНПА'!#REF!, "ошибка_2")))))))) -> 0 | BC14: =AZ14+2*BB14 -> 2.59 | BD14: =IF(BC14="","", IF(BC14=0,0,$BD$9)) -> 0 | BE14: =IF(BC14="","", IF(BC14=0,0,$BE$9)) -> 0 | BF14: =IF(BC14="","", IF($BD$9=0,0, IF(BC14<=13,20, IF(AND(BC14>13,BC14<=18),30, IF(AND(BC14>18,BC14<=23),40, IF(AND(BC14>23,BC14<=30),50, 60)))))) -> 0 | BG14: =IF(BC14="","",$BG$9) -> 0 | BH14: =IF(BC14="","",BC14+2*BD14*BE14*IF(BG14<=25,1,IF(BG14>33,2,1.5))) -> 2.59 | BI14: =IF(BC14="","",$BI$9) -> 0 | BJ14: =IF(BC14="","",$BJ$9) -> 0 | BK14: =IF(BJ14="","",IF(BJ14<>0,"×",0)) -> 0 | BL14: =IF(BK14="","", IF(BJ14<>0, IF(AND(BC14>7,BC14<=10),15, IF(AND(BC14>10,BC14<=13),20, IF(AND(BC14>13,BC14<=21),30, IF(AND(BC14>21,BC14<=31),40, IF(AND(BC14>31,BC14<=70),50, IF(AND(BC14>70,BC14<=80),60, "ошибка")))))),0)) -> 0 | BM14: =IF(BL14="","",$BM$9) -> 0 | BN14: =IF(BH14="","",BH14+2*BI14*BJ14) -> 2.59 | BO14: =IF(BN14="","",$BO$9) -> 0 | BP14: =IF(BO14="","",IF(BO14>0,$BP$9,0)) -> 0 | BQ14: =IF(BP14="","",IF(BP14>0,"×","")) | BR14: =IF(BN14="","",IF(BO14=0,0,IF(BN14<=19,30,IF(AND(BN14>19,BN14<=23),40,50)))) -> 0 | BS14: =IF(BO14="","",IF(BO14=0,0,$BS$9)) -> 0 | BT14: =IF(BN14="","",BN14+2*BO14*BP14*IF(BS14<=25,1,IF(BS14>33,2,1.5))) -> 2.59 | BU14: =0.85*BV14-0.1 -> 0.92 | BV14: =IF(BT14="","", IF(AND(BT14>'Данные ТНПА'!$K$8,BT14<='Данные ТНПА'!$L$8),'Данные ТНПА'!$N$8, IF(AND(BT14>'Данные ТНПА'!$K$9,BT14<='Данные ТНПА'!$L$9),'Данные ТНПА'!$N$9, IF(AND(BT14>'Данные ТНПА'!$K$10,BT14<='Данные ТНПА'!$L$10),'Данные ТНПА'!$N$10, IF(AND(BT14>'Данные ТНПА'!$K$11,BT14<='Данные ТНПА'!$L$11),'Данные ТНПА'!$N$11, IF(AND(BT14>'Данные ТНПА'!$K$12,BT14<='Данные ТНПА'!$L$12),'Данные ТНПА'!$N$12, IF(AND(BT14>'Данные ТНПА'!$K$13,BT14<='Данные ТНПА'!$L$13),'Данные ТНПА'!$N$13, IF(AND(BT14>'Данные ТНПА'!$K$14,BT14<='Данные ТНПА'!$L$14),'Данные ТНПА'!$N$14)))))))) -> 1.2 | BW14: =BT14+2*BV14 -> 4.99 | BX14: =IF(C14="а",F14*$BX$9*D14*IF(D14>1,1.007,1),0) -> 0 | BY14: =IF(C14="а",0,F14*$BY$9*D14*IF(D14>1,1.007,1)) -> 13.335 | BZ14: =IF(G14="мс",PI()*(P14/PI()+R14)*R14*$BZ$9*1.13*D14*1.007, PI()*(IF(I14=1,K14,L14)+R14)*R14*$BZ$9*D14*IF(D14>1,1.007,1)*IF(I14=1,1,(IF(F14>=4,1.1,1.07)))) -> 5.0264226 | CA14: =PI()*POWER(Y14,2)/4*$CA$9 -> #REF! | CB14: =IF(AA14="","", IF(AA14=2,SQRT((Z14*PI()/50)^2+1)*$CB$9*AA14,0)) -> 0 | CC14: =PI()*(Z14+AC14*AD14)*AC14*AD14*$CC$9*ROUND(100/(100-AG14),2) -> 0 | CD14: =PI()*(AH14+AI14*AJ14)*AI14*AJ14*$CD$9*ROUND(100/(100-AM14),2) -> 0 | CE14: =PI()*(AN14+AO14*AP14)*AO14*AP14*$CE$9*ROUND(100/(100-AS14),2) -> 0 | CF14: =PI()*(AT14+AU14*AV14)*AU14*AV14*$CF$9*ROUND(100/(100-AY14),2) -> 0 | CG14: =IF(CB14="","", IF(BB14=0,0, IF(AND(G14="мс",AC14=0),(PI()*BC14^2/4-D14*(O14+PI()*(P14/PI()+R14)*R14)-((POWER((N14+R14),2)*(D14*TAN(PI()*((D14-2)/(2*D14)))-(PI()*(D14-2)/2)))))*$CG$9, IF(AND(D14>1,OR(G14="ок",G14="мк")),(PI()*BC14^2/4-PI()*V14^2*(D14+2)/8-D14*(SIN(PI()*(D14-2)/D14))/2*(AB14/2-V14/2)^2)*$CG$9, PI()*(AB14+BB14)*BB14*1.07*$CG$9)))) -> 0 | CH14: =IF(BE14="","", IF(BD14=0,0, PI()*(BC14+BD14*BE14)*BD14*BE14*$CH$9*ROUND(100/(100-BG14),2))) -> 0 | CI14: =IF(BH14="","", PI()*(BH14+BI14*BJ14)*BI14*BJ14*$CI$9*ROUND(100/(100+BM14),2)) -> 0 | CJ14: =IF(BO14="","",PI()*(BN14+BO14*BP14)*BO14*BP14*$CJ$9*ROUND(100/(100-BS14),2)) -> 0 | CK14: =PI()*(BT14+BV14)*BV14*IF($BI$9>0,1.1,1.04)*$CK$9 -> 20.803275 | CL14: =BX14+BY14+BZ14+CK14 -> 39.164697
A15: =IF(D15="",CONCATENATE("Кабель ",IF(C15="а","А",""),$A$9),CONCATENATE("Кабель ",IF(C15="а","А",""),$A$9," ",D15,"*",F15,IF(G15="ок"," (ож)","")," - ",B15," ",IF(G15="мс"," фас. ",""),$A$2)) -> Кабель ВВГ 1*2,5 (ож) - 0,66 ГОСТ 16442-80 | B15: 0.66 | D15: 1 | E15: × | F15: 2.5 | G15: ок | H15: 1.79 | I15: 1 | J15: × | K15: =ROUNDUP(SQRT(F15/PI()*4),2) -> 1.79 | L15: 4.52 | Q15: =0.9*R15-0.1 -> 0.44 | R15: =IF(B15=0.66,VLOOKUP(F15,'Данные ТНПА'!$B$8:$C$16,2,0), IF(B15=1,VLOOKUP(F15,'Данные ТНПА'!$B$17:$C$37,2,0),"ошибка")) -> 0.6 | S15: =IF(I15=1,K15+2*Q15,L15+2*Q15) -> 2.67 | V15: =IF(I15=1,K15+2*R15,L15+2*R15) -> 2.99 | Y15: =IF(V15="","",ROUND(V15*IF(AND(D15=4,F15>16),0.414,IF(D15=5,0.702,0)),1)) -> 0 | Z15: =IF(R15="","", IF(G15="мс",2*(V15+(N15+R15)*(1/COS(PI()*(D15-2)/(2*D15))-1)), IF(D15=1,V15*1,IF(D15=2,V15*2,IF(D15=3,V15*2.15,IF(D15=4,V15*2.41,IF(D15=5,V15*2.7,"ошибка"))))))) -> 2.99 | AA15: =IF(G15="","",IF(G15="мс",$AA$9,0)) -> 0 | AB15: =IF(Z15="","",Z15) -> 2.99 | AC15: =IF(G15="","",IF(G15="мс",$AC$9,0)) -> 0 | AD15: =IF(AC15="","",IF(AC15>0,IF(AND(Z15>=10,Z15<=20),0.035,IF(Z15>20,0.05,"ошибка")),0)) -> 0 | AE15: =IF(Z15="","",IF(AND(G15="мс",AC15>0),"×","")) | AF15: =IF(AC15="","",IF(AC15>0,IF(AND(Z15>=10,Z15<=20),50,IF(Z15>20,60,"ошибка")),0)) -> 0 | AG15: =IF(AC15="","",IF(AC15>0,IF(AND(Z15>=10,Z15<=13),40,IF(AND(Z15>=13,Z15<=16),30,IF(Z15>16,25,"ошибка"))),0)) -> 0 | AH15: =IF(Z15="","",IF(AND(G15="мс",AC15>0),Z15+2*AC15*AD15*IF(AG15<=25,1,IF(AG15>33,2,1.5)),Z15)) -> 2.99 | AI15: =IF(OR($AI$9=0,AH15<=10,D15=1,AND(D15>1,F15<=10,OR(G15="ок",G15="мк"))),0,1) -> 0 | AJ15: =IF(AI15=0,0,$AJ$9) -> 0 | AK15: =IF(AI15="","",IF(AI15=0,0,"×")) -> 0 | AL15: =IF(AI15=0,0,$AL$9) -> 0 | AM15: =IF(AI15=0,0, IF(AND(AH15>10,AH15<=13),55, IF(AND(AH15>13,AH15<=15),45, IF(AND(AH15>15,AH15<=18),35, IF(AND(AH15>18,AH15<=20),30, IF(AH15>20,15, 0)))))) -> 0 | AN15: =AH15+2*AI15*AJ15*(IF(AM15<25,1,IF(AM15>33,2,1.5))) -> 2.99 | AO15: =IF(OR(AI15=0,AN15<=10,AN15>23,AND(D15>1,F15<=10,OR(G15="ок",G15="мк"))),0,1) -> 0 | AP15: =IF(OR(AO15=0,AN15>23),0,$AP$9) -> 0 | AQ15: =IF(OR(AN15>23,AO15=0),0,"×") -> 0 | AR15: =IF(OR(AN15>23,AO15=0),0,$AR$9) -> 0 | AS15: =IF(AO15=0,0, IF(AND(AH15>10,AH15<=13),55, IF(AND(AH15>13,AH15<=15),45, IF(AND(AH15>15,AH15<=18),35, IF(AND(AH15>18,AH15<=20),30, IF(AND(AH15>20,AH15<=23),15, 0)))))) -> 0 | AT15: =AN15+2*AO15*AP15*(IF(AS15<25,1,IF(AS15>33,2,1.5))) -> 2.99 | AU15: =IF(OR(AI15=0,D15=1,AN15<=23),0,1) -> 0 | AV15: =IF(OR(AU15=0,AN15<=23),0,$AV$9) -> 0 | AW15: =IF(OR(AN15<=23,AU15=0),0,"×") -> 0 | AX15: =IF(OR(AN15<=23,AU15=0),0,$AX$9) -> 0 | AY15: =IF(AU15=0,0,15) -> 0 | AZ15: =AT15+2*AU15*AV15*(IF(AY15<25,1,IF(AY15>33,2,1.5))) -> 2.99 | BA15: =IF(BB15=0,0, IF(D15=1, (IF(AND(AH15>'Данные ТНПА'!#REF!,AH15<='Данные ТНПА'!#REF!),'Данные ТНПА'!#REF!, IF(AND(AH15>'Данные ТНПА'!#REF!,AH15<='Данные ТНПА'!#REF!),'Данные ТНПА'!#REF!, IF(AND(AH15>'Данные ТНПА'!#REF!,AH15<='Данные ТНПА'!#REF!),'Данные ТНПА'!#REF!, IF(AND(AH15>'Данные ТНПА'!#REF!,AH15<='Данные ТНПА'!#REF!),'Данные ТНПА'!#REF!, IF(AND(AH15>'Данные ТНПА'!#REF!,AH15<='Данные ТНПА'!#REF!),'Данные ТНПА'!#REF!, IF(AND(AH15>'Данные ТНПА'!#REF!,AH15<='Данные ТНПА'!#REF!),'Данные ТНПА'!#REF!, "ошибка_1"))))))), IF(AND(AH15>'Данные ТНПА'!#REF!,AH15<='Данные ТНПА'!#REF!),'Данные ТНПА'!#REF!, IF(AND(AH15>'Данные ТНПА'!#REF!,AH15<='Данные ТНПА'!#REF!),'Данные ТНПА'!#REF!, IF(AND(AH15>'Данные ТНПА'!#REF!,AH15<='Данные ТНПА'!#REF!),'Данные ТНПА'!#REF!, IF(AND(AH15>'Данные ТНПА'!#REF!,AH15<='Данные ТНПА'!#REF!),'Данные ТНПА'!#REF!, IF(AND(AH15>'Данные ТНПА'!#REF!,AH15<='Данные ТНПА'!#REF!),'Данные ТНПА'!#REF!, IF(AND(AH15>'Данные ТНПА'!#REF!,AH15<='Данные ТНПА'!#REF!),'Данные ТНПА'!#REF!, "ошибка_2")))))))) -> 0 | BB15: =IF(OR($AI$9=0,AND(D15>1,F15>10)),0, IF(D15=1, (IF(AND(AH15>'Данные ТНПА'!#REF!,AH15<='Данные ТНПА'!#REF!),'Данные ТНПА'!#REF!, IF(AND(AH15>'Данные ТНПА'!#REF!,AH15<='Данные ТНПА'!#REF!),'Данные ТНПА'!#REF!, IF(AND(AH15>'Данные ТНПА'!#REF!,AH15<='Данные ТНПА'!#REF!),'Данные ТНПА'!#REF!, IF(AND(AH15>'Данные ТНПА'!#REF!,AH15<='Данные ТНПА'!#REF!),'Данные ТНПА'!#REF!, IF(AND(AH15>'Данные ТНПА'!#REF!,AH15<='Данные ТНПА'!#REF!),'Данные ТНПА'!#REF!, IF(AND(AH15>'Данные ТНПА'!#REF!,AH15<='Данные ТНПА'!#REF!),'Данные ТНПА'!#REF!, "ошибка_1"))))))), IF(AND(AH15>'Данные ТНПА'!#REF!,AH15<='Данные ТНПА'!#REF!),'Данные ТНПА'!#REF!, IF(AND(AH15>'Данные ТНПА'!#REF!,AH15<='Данные ТНПА'!#REF!),'Данные ТНПА'!#REF!, IF(AND(AH15>'Данные ТНПА'!#REF!,AH15<='Данные ТНПА'!#REF!),'Данные ТНПА'!#REF!, IF(AND(AH15>'Данные ТНПА'!#REF!,AH15<='Данные ТНПА'!#REF!),'Данные ТНПА'!#REF!, IF(AND(AH15>'Данные ТНПА'!#REF!,AH15<='Данные ТНПА'!#REF!),'Данные ТНПА'!#REF!, IF(AND(AH15>'Данные ТНПА'!#REF!,AH15<='Данные ТНПА'!#REF!),'Данные ТНПА'!#REF!, "ошибка_2")))))))) -> 0 | BC15: =AZ15+2*BB15 -> 2.99 | BD15: =IF(BC15="","", IF(BC15=0,0,$BD$9)) -> 0 | BE15: =IF(BC15="","", IF(BC15=0,0,$BE$9)) -> 0 | BF15: =IF(BC15="","", IF($BD$9=0,0, IF(BC15<=13,20, IF(AND(BC15>13,BC15<=18),30, IF(AND(BC15>18,BC15<=23),40, IF(AND(BC15>23,BC15<=30),50, 60)))))) -> 0 | BG15: =IF(BC15="","",$BG$9) -> 0 | BH15: =IF(BC15="","",BC15+2*BD15*BE15*IF(BG15<=25,1,IF(BG15>33,2,1.5))) -> 2.99 | BI15: =IF(BC15="","",$BI$9) -> 0 | BJ15: =IF(BC15="","",$BJ$9) -> 0 | BK15: =IF(BJ15="","",IF(BJ15<>0,"×",0)) -> 0 | BL15: =IF(BK15="","", IF(BJ15<>0, IF(AND(BC15>7,BC15<=10),15, IF(AND(BC15>10,BC15<=13),20, IF(AND(BC15>13,BC15<=21),30, IF(AND(BC15>21,BC15<=31),40, IF(AND(BC15>31,BC15<=70),50, IF(AND(BC15>70,BC15<=80),60, "ошибка")))))),0)) -> 0 | BM15: =IF(BL15="","",$BM$9) -> 0 | BN15: =IF(BH15="","",BH15+2*BI15*BJ15) -> 2.99 | BO15: =IF(BN15="","",$BO$9) -> 0 | BP15: =IF(BO15="","",IF(BO15>0,$BP$9,0)) -> 0 | BQ15: =IF(BP15="","",IF(BP15>0,"×","")) | BR15: =IF(BN15="","",IF(BO15=0,0,IF(BN15<=19,30,IF(AND(BN15>19,BN15<=23),40,50)))) -> 0 | BS15: =IF(BO15="","",IF(BO15=0,0,$BS$9)) -> 0 | BT15: =IF(BN15="","",BN15+2*BO15*BP15*IF(BS15<=25,1,IF(BS15>33,2,1.5))) -> 2.99 | BU15: =0.85*BV15-0.1 -> 0.92 | BV15: =IF(BT15="","", IF(AND(BT15>'Данные ТНПА'!$K$8,BT15<='Данные ТНПА'!$L$8),'Данные ТНПА'!$N$8, IF(AND(BT15>'Данные ТНПА'!$K$9,BT15<='Данные ТНПА'!$L$9),'Данные ТНПА'!$N$9, IF(AND(BT15>'Данные ТНПА'!$K$10,BT15<='Данные ТНПА'!$L$10),'Данные ТНПА'!$N$10, IF(AND(BT15>'Данные ТНПА'!$K$11,BT15<='Данные ТНПА'!$L$11),'Данные ТНПА'!$N$11, IF(AND(BT15>'Данные ТНПА'!$K$12,BT15<='Данные ТНПА'!$L$12),'Данные ТНПА'!$N$12, IF(AND(BT15>'Данные ТНПА'!$K$13,BT15<='Данные ТНПА'!$L$13),'Данные ТНПА'!$N$13, IF(AND(BT15>'Данные ТНПА'!$K$14,BT15<='Данные ТНПА'!$L$14),'Данные ТНПА'!$N$14)))))))) -> 1.2 | BW15: =BT15+2*BV15 -> 5.39 | BX15: =IF(C15="а",F15*$BX$9*D15*IF(D15>1,1.007,1),0) -> 0 | BY15: =IF(C15="а",0,F15*$BY$9*D15*IF(D15>1,1.007,1)) -> 22.225 | BZ15: =IF(G15="мс",PI()*(P15/PI()+R15)*R15*$BZ$9*1.13*D15*1.007, PI()*(IF(I15=1,K15,L15)+R15)*R15*$BZ$9*D15*IF(D15>1,1.007,1)*IF(I15=1,1,(IF(F15>=4,1.1,1.07)))) -> 6.0367588 | CA15: =PI()*POWER(Y15,2)/4*$CA$9 -> #REF! | CB15: =IF(AA15="","", IF(AA15=2,SQRT((Z15*PI()/50)^2+1)*$CB$9*AA15,0)) -> 0 | CC15: =PI()*(Z15+AC15*AD15)*AC15*AD15*$CC$9*ROUND(100/(100-AG15),2) -> 0 | CD15: =PI()*(AH15+AI15*AJ15)*AI15*AJ15*$CD$9*ROUND(100/(100-AM15),2) -> 0 | CE15: =PI()*(AN15+AO15*AP15)*AO15*AP15*$CE$9*ROUND(100/(100-AS15),2) -> 0 | CF15: =PI()*(AT15+AU15*AV15)*AU15*AV15*$CF$9*ROUND(100/(100-AY15),2) -> 0 | CG15: =IF(CB15="","", IF(BB15=0,0, IF(AND(G15="мс",AC15=0),(PI()*BC15^2/4-D15*(O15+PI()*(P15/PI()+R15)*R15)-((POWER((N15+R15),2)*(D15*TAN(PI()*((D15-2)/(2*D15)))-(PI()*(D15-2)/2)))))*$CG$9, IF(AND(D15>1,OR(G15="ок",G15="мк")),(PI()*BC15^2/4-PI()*V15^2*(D15+2)/8-D15*(SIN(PI()*(D15-2)/D15))/2*(AB15/2-V15/2)^2)*$CG$9, PI()*(AB15+BB15)*BB15*1.07*$CG$9)))) -> 0 | CH15: =IF(BE15="","", IF(BD15=0,0, PI()*(BC15+BD15*BE15)*BD15*BE15*$CH$9*ROUND(100/(100-BG15),2))) -> 0 | CI15: =IF(BH15="","", PI()*(BH15+BI15*BJ15)*BI15*BJ15*$CI$9*ROUND(100/(100+BM15),2)) -> 0 | CJ15: =IF(BO15="","",PI()*(BN15+BO15*BP15)*BO15*BP15*$CJ$9*ROUND(100/(100-BS15),2)) -> 0 | CK15: =PI()*(BT15+BV15)*BV15*IF($BI$9>0,1.1,1.04)*$CK$9 -> 22.998871 | CL15: =BX15+BY15+BZ15+CK15 -> 51.26063
